<?xml version="1.0" encoding="utf-8"?>

<robot name="rover_description">
  
  <link name="base_footprint" />

  <link name="base_link">
    <inertial>
      <origin
        xyz="-0.149084845881408 3.09150923927665E-05 -0.291336603762016"
        rpy="0 0 0" />
      <mass
        value="18.186723515946" />
      <inertia
        ixx="0.174935677420802"
        ixy="0"
        ixz="-0.00114013594122216"
        iyy="1.42229842100732"
        iyz="0"
        izz="1.31547459275806" />
    </inertial>

    <visual>
      <origin xyz="0 0 0" rpy="0 0 0" />
      <geometry>
        <mesh filename="file://$(arg rover_path)/meshes/robot_base.stl" />
      </geometry>
      <material name="">
        <color rgba="0.776470588235294 0.756862745098039 0.737254901960784 1" />
      </material>
    </visual>
    <collision>
      <origin xyz="0 0 0" rpy="0 0 0" />
      <geometry>
        <mesh filename="file://$(arg rover_path)/meshes/robot_base.stl" />
      </geometry>
    </collision>
  </link>

  <joint name="base_footprint_joint" type="fixed">
    <parent link="base_footprint"/>
    <child link="base_link"/>
    <origin xyz="0 0 .52019" rpy="0 0 0"/>
  </joint>

  <!-- Front right Wheel -->
  <link name="FR_wheel">
    <inertial>
      <origin
        xyz="0 0.05 0"
        rpy="0 0 0" />
      <mass
        value="0.95177" />
      <inertia
        ixx="0.0033805"
        ixy="0"
        ixz="0"
        iyy="0.0038955"
        iyz="0"
        izz="0.0033805" />
    </inertial>
    <visual>
      <origin
        xyz="0 0 0"
        rpy="0 0 0" />
      <geometry>
        <mesh
          filename="file://$(arg rover_path)/meshes/right_wheel.stl" />
      </geometry>
      <material
        name="">
        <color
          rgba="0.792156862745098 0.819607843137255 0.933333333333333 1" />
      </material>
    </visual>
    <collision>
      <origin
        xyz="0 0 0"
        rpy="0 0 0" />
      <geometry>
        <mesh
          filename="file://$(arg rover_path)/meshes/right_wheel.stl" />
      </geometry>
    </collision>
  </link>
  <joint name="FR_joint" type="continuous">
    <origin
      xyz="0.357788 -0.421409 -0.387336"
      rpy="0 0 0" />
    <parent link="base_link" />
    <child link="FR_wheel" />
    <axis xyz="0 1 0" />
    <limit
      effort="20"
      velocity="20" />
  </joint>

  <!-- Back right Wheel -->
  <link name="BR_wheel">
    <inertial>
      <origin
        xyz="0 0.05 0"
        rpy="0 0 0" />
      <mass
        value="0.95177" />
      <inertia
        ixx="0.0033805"
        ixy="0"
        ixz="0"
        iyy="0.0038955"
        iyz="0"
        izz="0.0033805" />
    </inertial>
    <visual>
      <origin
        xyz="0 0 0"
        rpy="0 0 0" />
      <geometry>
        <mesh
          filename="file://$(arg rover_path)/meshes/right_wheel.stl" />
      </geometry>
      <material
        name="">
        <color
          rgba="0.792156862745098 0.819607843137255 0.933333333333333 1" />
      </material>
    </visual>
    <collision>
      <origin
        xyz="0 0 0"
        rpy="0 0 0" />
      <geometry>
        <mesh
          filename="file://$(arg rover_path)/meshes/right_wheel.stl" />
      </geometry>
    </collision>
  </link>
  <joint name="BR_joint" type="continuous">
    <origin
      xyz="-0.377044 -0.421409 -0.383722"
      rpy="0 0 0" />
    <parent link="base_link" />
    <child link="BR_wheel" />
    <axis xyz="0 1 0" />
    <limit
      effort="20"
      velocity="20" />
  </joint>


  <!-- Front Left Wheel -->
  <link name="FL_wheel">
    <inertial>
      <origin
        xyz="0 0 0"
        rpy="0 0 0" />
      <mass
        value="0.95177" />
      <inertia
        ixx="0.0033805"
        ixy="0"
        ixz="0"
        iyy="0.0038955"
        iyz="0"
        izz="0.0033805" />
    </inertial>
    <visual>
      <origin
        xyz="0 0 0"
        rpy="0 0 0" />
      <geometry>
        <mesh
          filename="file://$(arg rover_path)/meshes/left_wheel.stl" />
      </geometry>
      <material
        name="">
        <color
          rgba="0.792156862745098 0.819607843137255 0.933333333333333 1" />
      </material>
    </visual>
    <collision>
      <origin
        xyz="0 0 0"
        rpy="0 0 0" />
      <geometry>
        <mesh
          filename="file://$(arg rover_path)/meshes/left_wheel.stl" />
      </geometry>
    </collision>
  </link>
  <joint name="FL_joint" type="continuous">
    <origin
      xyz="0.359424 0.412712 -0.386553"
      rpy="0 0 0" />
    <parent link="base_link" />
    <child link="FL_wheel" />
    <axis xyz="0 1 0" />
    <limit
      effort="20"
      velocity="20" />
  </joint>

  <!-- back Left Wheel -->
  <link name="BL_wheel">
    <inertial>
      <origin
        xyz="0 0 0"
        rpy="0 0 0" />
      <mass
        value="0.95177" />
      <inertia
        ixx="0.0033805"
        ixy="0"
        ixz="0"
        iyy="0.0038955"
        iyz="0"
        izz="0.0033805" />
    </inertial>
    <visual>
      <origin
        xyz="0 0 0"
        rpy="0 0 0" />
      <geometry>
        <mesh
          filename="file://$(arg rover_path)/meshes/left_wheel.stl" />
      </geometry>
      <material
        name="">
        <color
          rgba="0.792156862745098 0.819607843137255 0.933333333333333 1" />
      </material>
    </visual>
    <collision>
      <origin
        xyz="0 0 0"
        rpy="0 0 0" />
      <geometry>
        <mesh
          filename="file://$(arg rover_path)/meshes/left_wheel.stl" />
      </geometry>
    </collision>
  </link>
  <joint name="BL_joint" type="continuous">
    <origin
      xyz="-0.385612 0.413443 -0.386925"
      rpy="0 0 0" />
    <parent link="base_link" />
    <child link="BL_wheel" />
    <axis xyz="0 1 0" />
    <limit
      effort="20"
      velocity="20" />
  </joint>

</robot>