<?xml version="1.0" encoding="utf-8"?>
<!-- This URDF was automatically created by SolidWorks to URDF Exporter! Originally created by Stephen Brawner (brawner@gmail.com) 
     Commit Version: 1.6.0-4-g7f85cfe  Build Version: 1.6.7995.38578
     For more information, please see http://wiki.ros.org/sw_urdf_exporter -->
<robot name="rover_description">
  
  <!-- <link name="base_footprint" /> -->

  <link
    name="base_link">
    <inertial>
      <origin
        xyz="-0.015849188161993 -0.0187715062637396 -0.239600824235464"
        rpy="0 0 0" />
      <mass
        value="18.9097180944353" />
      <inertia
        ixx="0.175714926339788"
        ixy="5.59199856757057E-05"
        ixz="-0.00114013593020295"
        iyy="1.42250580205738"
        iyz="-1.33765976099103E-05"
        izz="1.31620569058488" />
    </inertial>
    <visual>
      <origin
        xyz="0 0 0"
        rpy="0 0 0" />
      <geometry>
        <mesh
          filename="file://$(arg rover_path)/meshes/base_link.STL" />
      </geometry>
      <material
        name="">
        <color
          rgba="0.776470588235294 0.756862745098039 0.737254901960784 1" />
      </material>
    </visual>
    <collision>
      <origin
        xyz="0 0 0"
        rpy="0 0 0" />
      <geometry>
        <mesh
          filename="file://$(arg rover_path)/meshes/base_link.STL" />
      </geometry>
    </collision>
  </link>
  <link
    name="joint_1">
    <inertial>
      <origin
        xyz="-4.83698377407027E-07 0.0407313066510072 -7.95011263043932E-06"
        rpy="0 0 0" />
      <mass
        value="0.978511890736954" />
      <inertia
        ixx="0.00392622361603203"
        ixy="-3.19818061675555E-08"
        ixz="3.00318438598734E-11"
        iyy="0.00390380300501488"
        iyz="4.84067146482592E-07"
        izz="0.00392622284986234" />
    </inertial>
    <visual>
      <origin
        xyz="0 0 0"
        rpy="0 0 0" />
      <geometry>
        <mesh
          filename="file://$(arg rover_path)/meshes/joint_1.STL" />
      </geometry>
      <material
        name="">
        <color
          rgba="0.792156862745098 0.819607843137255 0.933333333333333 1" />
      </material>
    </visual>
    <collision>
      <origin
        xyz="0 0 0"
        rpy="0 0 0" />
      <geometry>
        <mesh
          filename="file://$(arg rover_path)/meshes/joint_1.STL" />
      </geometry>
    </collision>
  </link>
  <joint
    name="wheel_1"
    type="continuous">
    <origin
      xyz="-0.39068 -0.41211 -0.38728"
      rpy="0 0 0" />
    <parent
      link="base_link" />
    <child
      link="joint_1" />
    <axis
      xyz="0 -1 0" />
    <limit
      lower="0"
      upper="0"
      effort="20"
      velocity="20" />
  </joint>
  <link
    name="joint_2">
    <inertial>
      <origin
        xyz="7.14468498919096E-07 -0.0407313061110303 -7.93270370674781E-06"
        rpy="0 0 0" />
      <mass
        value="0.978511903090739" />
      <inertia
        ixx="0.00392622359053013"
        ixy="-1.79047218636518E-08"
        ixz="-7.73104380645234E-12"
        iyy="0.00390380295154401"
        iyz="-4.84791975184863E-07"
        izz="0.00392622282216524" />
    </inertial>
    <visual>
      <origin
        xyz="0 0 0"
        rpy="0 0 0" />
      <geometry>
        <mesh
          filename="file://$(arg rover_path)/meshes/joint_2.STL" />
      </geometry>
      <material
        name="">
        <color
          rgba="0.792156862745098 0.819607843137255 0.933333333333333 1" />
      </material>
    </visual>
    <collision>
      <origin
        xyz="0 0 0"
        rpy="0 0 0" />
      <geometry>
        <mesh
          filename="file://$(arg rover_path)/meshes/joint_2.STL" />
      </geometry>
    </collision>
  </link>
  <joint
    name="wheel_2"
    type="continuous">
    <origin
      xyz="-0.390678841233882 0.374505301267686 -0.387276310870224"
      rpy="0 0 0" />
    <parent
      link="base_link" />
    <child
      link="joint_2" />
    <axis
      xyz="0 -1 0" />
    <limit
      lower="0"
      upper="0"
      effort="20"
      velocity="20" />
  </joint>
  <link
    name="joint_3">
    <inertial>
      <origin
        xyz="-2.0872336782829E-06 -0.040731306653796 -7.68646280835394E-06"
        rpy="0 0 0" />
      <mass
        value="0.978511891131766" />
      <inertia
        ixx="0.00392622351933036"
        ixy="-1.85286887260406E-07"
        ixz="-2.5627269364985E-10"
        iyy="0.00390380300505671"
        iyz="-4.48344295864835E-07"
        izz="0.00392622294668659" />
    </inertial>
    <visual>
      <origin
        xyz="0 0 0"
        rpy="0 0 0" />
      <geometry>
        <mesh
          filename="file://$(arg rover_path)/meshes/joint_3.STL" />
      </geometry>
      <material
        name="">
        <color
          rgba="0.792156862745098 0.819607843137255 0.933333333333333 1" />
      </material>
    </visual>
    <collision>
      <origin
        xyz="0 0 0"
        rpy="0 0 0" />
      <geometry>
        <mesh
          filename="file://$(arg rover_path)/meshes/joint_3.STL" />
      </geometry>
    </collision>
  </link>
  <joint
    name="wheel_3"
    type="continuous">
    <origin
      xyz="0.349292562707965 0.374648069983417 -0.387276310870224"
      rpy="0 0 0" />
    <parent
      link="base_link" />
    <child
      link="joint_3" />
    <axis
      xyz="0 -1 0" />
    <limit
      lower="0"
      upper="0"
      effort="20"
      velocity="20" />
  </joint>
  <link
    name="joint_4">
    <inertial>
      <origin
        xyz="-3.21675105779962E-06 0.0407313061117895 -7.286341051016E-06"
        rpy="0 0 0" />
      <mass
        value="0.97851190354741" />
      <inertia
        ixx="0.00392622351648147"
        ixy="1.38258628304703E-07"
        ixz="-2.26918202540043E-10"
        iyy="0.00390380295158154"
        iyz="4.65003645043901E-07"
        izz="0.00392622289627493" />
    </inertial>
    <visual>
      <origin
        xyz="0 0 0"
        rpy="0 0 0" />
      <geometry>
        <mesh
          filename="file://$(arg rover_path)/meshes/joint_4.STL" />
      </geometry>
      <material
        name="">
        <color
          rgba="0.792156862745098 0.819607843137255 0.933333333333333 1" />
      </material>
    </visual>
    <collision>
      <origin
        xyz="0 0 0"
        rpy="0 0 0" />
      <geometry>
        <mesh
          filename="file://$(arg rover_path)/meshes/joint_4.STL" />
      </geometry>
    </collision>
  </link>
  <joint
    name="wheel_4"
    type="continuous">
    <origin
      xyz="0.349292562707965 -0.412250550889761 -0.387276310870224"
      rpy="0 0 0" />
    <parent
      link="base_link" />
    <child
      link="joint_4" />
    <axis
      xyz="0 -1 0" />
    <limit
      lower="0"
      upper="0"
      effort="20"
      velocity="20" />
  </joint>
</robot>