<?xml version="1.0" encoding="utf-8"?>
<!-- This URDF was automatically created by SolidWorks to URDF Exporter! Originally created by Stephen Brawner (brawner@gmail.com) 
     Commit Version: 1.6.0-4-g7f85cfe  Build Version: 1.6.7995.38578
     For more information, please see http://wiki.ros.org/sw_urdf_exporter -->
<robot name="rover_description">
  
  <!-- <link name="base_footprint" /> -->

  <link name="base_link">
    <inertial>
      <origin
        xyz="-0.0187704819491408 0.0156823186449976 -0.238133412115633"
        rpy="0 0 0" />
      <mass
        value="18.2799897993079" />
      <inertia
        ixx="1.42234082954751"
        ixy="-5.59198852274269E-05"
        ixz="-1.33765976099123E-05"
        iyy="0.175551238923741"
        iyz="0.00114013593020314"
        izz="1.31605560837416" />
    </inertial>
    <visual>
      <origin
        xyz="0 0 0"
        rpy="0 0 0" />
      <geometry>
        <mesh
          filename="file://$(arg rover_path)/meshes/base_link.STL" />
      </geometry>
      <material
        name="">
        <color
          rgba="0.776470588235294 0.756862745098039 0.737254901960784 1" />
      </material>
    </visual>
    <collision>
      <origin
        xyz="0 0 0"
        rpy="0 0 0" />
      <geometry>
        <mesh
          filename="file://$(arg rover_path)/meshes/base_link.STL" />
      </geometry>
    </collision>
  </link>
  <link
    name="joint_1">
    <inertial>
      <origin
        xyz="-0.0407313066510072 4.83698377407027E-07 7.95011263043932E-06"
        rpy="0 0 0" />
      <mass
        value="0.978511890736954" />
      <inertia
        ixx="0.00390380300501488"
        ixy="-3.19818061675711E-08"
        ixz="4.84067146482601E-07"
        iyy="0.00392622361603202"
        iyz="3.00318438613888E-11"
        izz="0.00392622284986233" />
    </inertial>
    <visual>
      <origin
        xyz="0 0 0"
        rpy="0 0 0" />
      <geometry>
        <mesh
          filename="file://$(arg rover_path)/meshes/joint_1.STL" />
      </geometry>
      <material
        name="">
        <color
          rgba="0.792156862745098 0.819607843137255 0.933333333333333 1" />
      </material>
    </visual>
    <collision>
      <origin
        xyz="0 0 0"
        rpy="0 0 0" />
      <geometry>
        <mesh
          filename="file://$(arg rover_path)/meshes/joint_1.STL" />
      </geometry>
    </collision>
  </link>
  <joint
    name="wheel_1"
    type="continuous">
    <origin
      xyz="-0.41211 0.39068 -0.38728"
      rpy="3.1416 0 3.1416" />
    <parent
      link="base_link" />
    <child
      link="joint_1" />
    <axis
      xyz="-1 0 0" />
    <limit
      lower="0"
      upper="0"
      effort="20"
      velocity="20" />
  </joint>
  <link
    name="joint_2">
    <inertial>
      <origin
        xyz="0.0407313061110303 -7.14468498919096E-07 7.93270370674781E-06"
        rpy="0 0 0" />
      <mass
        value="0.978511903090739" />
      <inertia
        ixx="0.003903802951544"
        ixy="-1.79047218636934E-08"
        ixz="-4.8479197518485E-07"
        iyy="0.00392622359053013"
        iyz="-7.73104380465571E-12"
        izz="0.00392622282216524" />
    </inertial>
    <visual>
      <origin
        xyz="0 0 0"
        rpy="0 0 0" />
      <geometry>
        <mesh
          filename="file://$(arg rover_path)/meshes/joint_2.STL" />
      </geometry>
      <material
        name="">
        <color
          rgba="0.792156862745098 0.819607843137255 0.933333333333333 1" />
      </material>
    </visual>
    <collision>
      <origin
        xyz="0 0 0"
        rpy="0 0 0" />
      <geometry>
        <mesh
          filename="file://$(arg rover_path)/meshes/joint_2.STL" />
      </geometry>
    </collision>
  </link>
  <joint
    name="wheel_2"
    type="continuous">
    <origin
      xyz="0.37451 0.39068 -0.38728"
      rpy="3.1416 0 3.1416" />
    <parent
      link="base_link" />
    <child
      link="joint_2" />
    <axis
      xyz="1 0 0" />
    <limit
      lower="0"
      upper="0"
      effort="20"
      velocity="20" />
  </joint>
  <link
    name="joint_3">
    <inertial>
      <origin
        xyz="0.040731308982988 3.26565934316569E-06 7.26455152644245E-06"
        rpy="0 0 0" />
      <mass
        value="0.978512007649862" />
      <inertia
        ixx="0.00390380296089394"
        ixy="-2.53238783219728E-07"
        ixz="-4.13780082731324E-07"
        iyy="0.00392622340401242"
        iyz="-3.32298254843631E-10"
        izz="0.00392622301809126" />
    </inertial>
    <visual>
      <origin
        xyz="0 0 0"
        rpy="0 0 0" />
      <geometry>
        <mesh
          filename="file://$(arg rover_path)/meshes/joint_3.STL" />
      </geometry>
      <material
        name="">
        <color
          rgba="0.792156862745098 0.819607843137255 0.933333333333333 1" />
      </material>
    </visual>
    <collision>
      <origin
        xyz="0 0 0"
        rpy="0 0 0" />
      <geometry>
        <mesh
          filename="file://$(arg rover_path)/meshes/joint_3.STL" />
      </geometry>
    </collision>
  </link>
  <joint
    name="wheel_3"
    type="continuous">
    <origin
      xyz="0.37465 -0.34929 -0.38728"
      rpy="3.1416 0 3.1416" />
    <parent
      link="base_link" />
    <child
      link="joint_3" />
    <axis
      xyz="1 0 0" />
    <limit
      lower="0"
      upper="0"
      effort="20"
      velocity="20" />
  </joint>
  <link
    name="joint_4">
    <inertial>
      <origin
        xyz="-0.040731308985328 4.31854407578758E-06 6.69241487549765E-06"
        rpy="0 0 0" />
      <mass
        value="0.978512007561894" />
      <inertia
        ixx="0.00390380296085884"
        ixy="2.09401175396365E-07"
        ixz="4.37601400837618E-07"
        iyy="0.00392622343571838"
        iyz="-3.11744121537734E-10"
        izz="0.00392622298640107" />
    </inertial>
    <visual>
      <origin
        xyz="0 0 0"
        rpy="0 0 0" />
      <geometry>
        <mesh
          filename="file://$(arg rover_path)/meshes/joint_4.STL" />
      </geometry>
      <material
        name="">
        <color
          rgba="0.792156862745098 0.819607843137255 0.933333333333333 1" />
      </material>
    </visual>
    <collision>
      <origin
        xyz="0 0 0"
        rpy="0 0 0" />
      <geometry>
        <mesh
          filename="file://$(arg rover_path)/meshes/joint_4.STL" />
      </geometry>
    </collision>
  </link>
  <joint
    name="wheel_4"
    type="continuous">
    <origin
      xyz="-0.41225 -0.34929 -0.38728"
      rpy="3.1416 0 3.1416" />
    <parent
      link="base_link" />
    <child
      link="joint_4" />
    <axis
      xyz="-1 0 0" />
    <limit
      lower="0"
      upper="0"
      effort="20"
      velocity="20" />
  </joint>
</robot>